Workbook
Name ComponentType_List: Lookups!$B$2:$B$27
Name Def_BCF: Lookups!$AF$2:$AF$4
Name Def_CFI: Lookups!$J$2:$J$12
Name Def_CML: Lookups!$F$2:$F$14
Name Def_CND: Lookups!$H$2:$H$11
Name Def_CRK: Lookups!$L$2:$L$10
Name Def_DFI: Lookups!$N$2:$N$17
Name Def_ENV: Lookups!$R$2:$R$13
Name Def_EWF: Lookups!$P$2:$P$3
Name Def_FDS: Lookups!$T$2:$T$18
Name Def_FH: Lookups!$AD$2:$AD$3
Name Def_GHK: Lookups!$V$2:$V$8
Name Def_MSI: Lookups!$X$2:$X$7
Name Def_PF: Lookups!$AH$2:$AH$4
Name Def_SIE: Lookups!$AB$2:$AB$5
Name Def_THR: Lookups!$Z$2:$Z$6
Name DefCat_List: Lookups!$A$2:$A$16
Name Focus_BCF: Lookups!$AX$2:$AX$3
Name Focus_CFI: Lookups!$AM$2:$AM$6
Name Focus_CML: Lookups!$AK$2:$AK$8
Name Focus_CND: Lookups!$AL$2:$AL$5
Name Focus_CRK: Lookups!$AN$2:$AN$4
Name Focus_DFI: Lookups!$AO$2:$AO$10
Name Focus_ENV: Lookups!$AQ$2:$AQ$6
Name Focus_EWF: Lookups!$AP$2:$AP$3
Name Focus_FDS: Lookups!$AR$2:$AR$10
Name Focus_FH: Lookups!$AW$2:$AW$3
Name Focus_GHK: Lookups!$AS$2:$AS$2
Name Focus_MSI: Lookups!$AT$2:$AT$3
Name Focus_PF: Lookups!$AY$2:$AY$4
Name Focus_SIE: Lookups!$AV$2:$AV$4
Name Focus_THR: Lookups!$AU$2:$AU$2
Name Mech_BCF: Lookups!$AG$2:$AG$3
Name Mech_CFI: Lookups!$K$2:$K$7
Name Mech_CML: Lookups!$G$2:$G$7
Name Mech_CND: Lookups!$I$2:$I$5
Name Mech_CRK: Lookups!$M$2:$M$7
Name Mech_DFI: Lookups!$O$2:$O$8
Name Mech_ENV: Lookups!$S$2:$S$8
Name Mech_EWF: Lookups!$Q$2:$Q$6
Name Mech_FDS: Lookups!$U$2:$U$11
Name Mech_FH: Lookups!$AE$2:$AE$2
Name Mech_GHK: Lookups!$W$2:$W$6
Name Mech_MSI: Lookups!$Y$2:$Y$4
Name Mech_PF: Lookups!$AI$2:$AI$4
Name Mech_SIE: Lookups!$AC$2:$AC$5
Name Mech_THR: Lookups!$AA$2:$AA$4
Name Priority_List: Lookups!$C$2:$C$6
Name Risk_List: Lookups!$E$2:$E$4
Name SiteList: Details!$A$2:$A$11
Name Sub_AccessLadder: Lookups!$BH$2
Name Sub_Beams: Lookups!$BU$2
Name Sub_Bracing: Lookups!$BV$2
Name Sub_BuildingStructure: Lookups!$BB$2
Name Sub_CableTray: Lookups!$BL$2
Name Sub_CableTraySupport: Lookups!$BR$2
Name Sub_CatwalksWalkways: Lookups!$BN$2
Name Sub_ClarifierTank: Lookups!$BX$2
Name Sub_Column: Lookups!$BJ$2
Name Sub_ConcreteFloor: Lookups!$BF$2

Sheet Instructions
B1: STRUCTURAL INTEGRITY ASSESSMENT — HOW TO USE THIS WORKBOOK
B2: A field + analysis tool for asset / structural integrity inspections
B4: 1 · SET UP THE ASSET REGISTRY (one-time, per asset)
B5: Open the Asset Registry tab. Ensure each asset has a row with its Site, Parent Asset, Asset ID, Asset Group, Asset Type and Location, and is marked In Scope. The Inspections tab pulls these automatically — accurate registry data means accurate records.
B7: 2 · RECORD AN INSPECTION (main workflow)
B8: Go to the Inspections tab and read the yellow banner. GREY columns auto-fill from the registry — do not type in them. TEAL columns are yours to fill.
B9: Fill the teal columns left to right: Inspection Date (yyyy-mm-dd) · Inspector Name · PPE Requirements Met (Yes/No) · Component Type.
B10: Deficiency Category — pick this FIRST. It drives the next two dropdowns.
B11: Detailed Description — now shows only the deficiencies relevant to the category you chose.
B12: Potential Failure Cause — shows only the mechanisms relevant to that category.
B13: Vibration Present · Impact Risk · Safety Risk.
B14: Priority Rating (P1–P5) — the grey Priority Description fills in automatically.
... B30: Legend: GREY columns auto-fill from the Asset Registry · TEAL columns are filled by the inspector.

Sheet Asset Registry
A1: Asset Register
A3: Site | B3: Parent Asset | C3: Asset ID | D3: Category | E3: Component | F3: Location Description | G3: Access Notes | H3: In Scope | I3: Last Inspection Date | J3: Comments
A4: Bell Mine | B4: WTP | C4: No ID Yet
A5: Bell Mine | B5: Admin Building | C5: No ID Yet

Sheet Inspections
A1: Inspections
A2: ▶ Fill the TEAL columns. GREY columns auto-fill from the Asset Registry — do not type in them. Tip: choose the Deficiency Category first — it filters the Detailed Description and Potential Failure Cause lists.
A3: Record ID | B3: Site | C3: Asset ID | D3: Parent Asset | E3: Category | F3: Component | G3: Location Description | H3: Inspection Date | I3: Inspector Name | J3: PPE Requirements Met | K3: Component Type | L3: Sub-Component | M3: Deficiency Category | N3: Detailed Description | O3: Mechanisms | P3: Vibration Present | Q3: Consequence Severity | R3: Most-Affected Consequence | S3: Priority Rating | T3: Priority Description | U3: Recommended Action | V3: Immediate Site Notification | W3: Further Investigation Required | X3: NDT Required | Y3: Focus Area | Z3: Likelihood | AA3: Risk Rank | AB3: Risk Rating
A4: REVIEW-20260703025411 | B4: Bell Mine | C4: No ID Yet | D4: WTP | E4: Building Envelope | H4: 46205 | I4: Neyo | J4: Yes | K4: Roofing systems | L4: Metal / panel | M4: EWF - Envelope Failure | N4: Poor maintenance (trip hazards) | O4: jhsjhgsD | P4: No | Q4: 1 - Negligible | R4: Health & Safety | S4: P1 | T4: Critical Condition - Immediate action required; repair within 60 days max | U4: srgfdgdfgfd | V4: Yes | W4: No | X4: No | Y4: Structural integrity | ASSET NOT IN REGISTRY - pending verification | Z4: A - Almost Certain | AA4: 11 | AB4: Medium
A5: REVIEW-20260703140822 | B5: Bell Mine | C5: No ID Yet | D5: Admin Building | E5: Building Envelope | H5: 46206 | I5: Niyi | J5: Yes | K5: Roofing systems | L5: Metal / panel | M5: EWF - Envelope Failure | N5: Water ingress / leaks | O5: Water Ingress | P5: No | Q5: 3 - Moderate | R5: Health & Safety | S5: P2 | T5: Poor Condition - Repair actions needed within 12 months | U5: Fix the roof | V5: Yes | W5: No | X5: Yes | Y5: Primary framing | ASSET NOT IN REGISTRY - pending verification | Z5: B - Likely | AA5: 17 | AB5: High

Sheet Photo_Register
A1: Photo Register
A3: Record ID | B3: Site | C3: Asset ID | D3: Parent Asset | E3: Date Taken | F3: Inspector Name | G3: Photo Description | H3: File Path / Hyperlink
A4: REVIEW-20260703025411 | B4: Bell Mine | D4: WTP | E4: 46205 | F4: Neyo | G4: Inspection photo(s) - EWF - Envelope Failure | H4: https://nerizonltd-my.sharepoint.com/personal/aaraoye_nerizon_ca/Documents/NACS/NER-GC%20Doc/Structural%20Integrity/Inspection/Inspection%20Photos/INSP_20260703025402_4_1e16bdde-9138-4b0c-8644-21db416852d8.png
A5: REVIEW-20260703140822 | B5: Bell Mine | D5: Admin Building | E5: 46206 | F5: Niyi | G5: Inspection photo(s) - EWF - Envelope Failure | H5: https://nerizonltd-my.sharepoint.com/personal/aaraoye_nerizon_ca/Documents/NACS/NER-GC%20Doc/Structural%20Integrity/Inspection/Inspection%20Photos/INSP_20260703140812_5_e1e86a9f-7b09-40df-96a9-ca2ca4468d61.png

Sheet Site Summary
A1: STRUCTURAL INTEGRITY ASSESSMENT — INSPECTION SUMMARY
A2: Live counts from the Inspections tab — updates automatically as inspectors record findings
B4: TOTAL DEFICIENCIES | D4: P1 — CRITICAL | F4: IMMEDIATE NOTIFY | H4: FURTHER INVESTIGATION | J4: NDT REQUIRED
B5: =COUNTIF(Table3[Deficiency Category],"?*") -> 2 | D5: =COUNTIF(Table3[Priority Rating],"P1") -> 1 | F5: =COUNTIF(Table3[Immediate Site Notification],"Yes") -> 2 | H5: =COUNTIF(Table3[Further Investigation Required],"Yes") -> 0 | J5: =COUNTIF(Table3[NDT Required],"Yes") -> 1
A8: DEFICIENCY BY CATEGORY | B8: Count | C8: % of Total | E8: PRIORITY | F8: Count | G8: Condition | P8: helper — unique sites (auto)
A9: =Lookups!A2 -> CML - Corrosion & Material Loss | B9: =COUNTIF(Table3[Deficiency Category],$A9) -> 0 | C9: =IFERROR(B9/$B$24,0) -> 0 | E9: =Details!I2 -> P1 | F9: =COUNTIF(Table3[Priority Rating],$E9) -> 1 | G9: =Details!J2 -> Critical Condition - Immediate action required | P9: {=_xlfn._xlws.SORT(_xlfn.UNIQUE(_xlfn._xlws.FILTER(Details!A2:A40,Details!A2:A40<>"")))} -> Bell Mine
A10: =Lookups!A3 -> CND - Concrete Deterioration | B10: =COUNTIF(Table3[Deficiency Category],$A10) -> 0 | C10: =IFERROR(B10/$B$24,0) -> 0 | E10: =Details!I3 -> P2 | F10: =COUNTIF(Table3[Priority Rating],$E10) -> 1 | G10: =Details!J3 -> Poor Condition - Repair actions needed within 12 months | P10: Blackbird Mine
A11: =Lookups!A4 -> CFI - Connection & Joint Failures | B11: =COUNTIF(Table3[Deficiency Category],$A11) -> 0 | C11: =IFERROR(B11/$B$24,0) -> 0 | E11: =Details!I4 -> P3 | F11: =COUNTIF(Table3[Priority Rating],$E11) -> 0 | G11: =Details!J4 -> Bad Condition - Repairs needed within 24 to 36 months | P11: Brenda Mine
A12: =Lookups!A5 -> CRK - Cracking Mechanisms | B12: =COUNTIF(Table3[Deficiency Category],$A12) -> 0 | C12: =IFERROR(B12/$B$24,0) -> 0 | E12: =Details!I5 -> P4 | F12: =COUNTIF(Table3[Priority Rating],$E12) -> 0 | G12: =Details!J5 -> Fair Condition - Monitor before next scheduled inspection | P12: Brunswick Mine
A13: =Lookups!A6 -> DFI - Deformation & Mechanical Damage | B13: =COUNTIF(Table3[Deficiency Category],$A13) -> 0 | C13: =IFERROR(B13/$B$24,0) -> 0 | E13: =Details!I6 -> P5 | F13: =COUNTIF(Table3[Priority Rating],$E13) -> 0 | G13: =Details!J6 -> Good Condition - No repairs required | P13: Geco/Wilroy Mine
A14: =Lookups!A7 -> EWF - Envelope Failure | B14: =COUNTIF(Table3[Deficiency Category],$A14) -> 2 | C14: =IFERROR(B14/$B$24,0) -> 1 | E14: Total | F14: =SUM(F9:F13) -> 2 | P14: Grey Eagle Mine
A15: =Lookups!A8 -> ENV - Environmental & External Damage | B15: =COUNTIF(Table3[Deficiency Category],$A15) -> 0 | C15: =IFERROR(B15/$B$24,0) -> 0 | P15: Heath Steele Mine
A16: =Lookups!A9 -> FDS - Foundation & Settlement | B16: =COUNTIF(Table3[Deficiency Category],$A16) -> 0 | C16: =IFERROR(B16/$B$24,0) -> 0 | E16: SITE | F16: Count | P16: Matagami Mine
A17: =Lookups!A10 -> GHK - General Housekeeping & Maintenance | B17: =COUNTIF(Table3[Deficiency Category],$A17) -> 0 | C17: =IFERROR(B17/$B$24,0) -> 0 | E17: {=IFERROR(INDEX(_xlfn.ANCHORARRAY($P$9),ROW()-16),"")} -> Bell Mine | F17: =IF($E17="","",COUNTIFS(Table3[Site],$E17,Table3[Deficiency Category],"?*")) -> 2 | P17: Mattabi Mine
A18: =Lookups!A11 -> MSI - Modification & Structural Integrity | B18: =COUNTIF(Table3[Deficiency Category],$A18) -> 0 | C18: =IFERROR(B18/$B$24,0) -> 0 | E18: {=IFERROR(INDEX(_xlfn.ANCHORARRAY($P$9),ROW()-16),"")} -> Blackbird Mine | F18: =IF($E18="","",COUNTIFS(Table3[Site],$E18,Table3[Deficiency Category],"?*")) -> 0 | P18: Montcalm Mine
A19: =Lookups!A12 -> THR - Fire & Thermal Damage | B19: =COUNTIF(Table3[Deficiency Category],$A19) -> 0 | C19: =IFERROR(B19/$B$24,0) -> 0 | E19: {=IFERROR(INDEX(_xlfn.ANCHORARRAY($P$9),ROW()-16),"")} -> Brenda Mine | F19: =IF($E19="","",COUNTIFS(Table3[Site],$E19,Table3[Deficiency Category],"?*")) -> 0
A20: =Lookups!A13 -> SIE - Soil Instability & Erosion | B20: =COUNTIF(Table3[Deficiency Category],$A20) -> 0 | C20: =IFERROR(B20/$B$24,0) -> 0 | E20: {=IFERROR(INDEX(_xlfn.ANCHORARRAY($P$9),ROW()-16),"")} -> Brunswick Mine | F20: =IF($E20="","",COUNTIFS(Table3[Site],$E20,Table3[Deficiency Category],"?*")) -> 0
A21: =Lookups!A14 -> FH - Frost Heave | B21: =COUNTIF(Table3[Deficiency Category],$A21) -> 0 | C21: =IFERROR(B21/$B$24,0) -> 0 | E21: {=IFERROR(INDEX(_xlfn.ANCHORARRAY($P$9),ROW()-16),"")} -> Geco/Wilroy Mine | F21: =IF($E21="","",COUNTIFS(Table3[Site],$E21,Table3[Deficiency Category],"?*")) -> 0
A22: =Lookups!A15 -> BCF - Bearing Capacity Failure | B22: =COUNTIF(Table3[Deficiency Category],$A22) -> 0 | C22: =IFERROR(B22/$B$24,0) -> 0 | E22: {=IFERROR(INDEX(_xlfn.ANCHORARRAY($P$9),ROW()-16),"")} -> Grey Eagle Mine | F22: =IF($E22="","",COUNTIFS(Table3[Site],$E22,Table3[Deficiency Category],"?*")) -> 0
A23: =Lookups!A16 -> PF - Pile Foundations | B23: =COUNTIF(Table3[Deficiency Category],$A23) -> 0 | C23: =IFERROR(B23/$B$24,0) -> 0 | E23: {=IFERROR(INDEX(_xlfn.ANCHORARRAY($P$9),ROW()-16),"")} -> Heath Steele Mine | F23: =IF($E23="","",COUNTIFS(Table3[Site],$E23,Table3[Deficiency Category],"?*")) -> 0
A24: Total | B24: =SUM(B9:B23) -> 2 | C24: =IFERROR(B24/$B$24,0) -> 1 | E24: {=IFERROR(INDEX(_xlfn.ANCHORARRAY($P$9),ROW()-16),"")} -> Matagami Mine | F24: =IF($E24="","",COUNTIFS(Table3[Site],$E24,Table3[Deficiency Category],"?*")) -> 0
E25: {=IFERROR(INDEX(_xlfn.ANCHORARRAY($P$9),ROW()-16),"")} -> Mattabi Mine | F25: =IF($E25="","",COUNTIFS(Table3[Site],$E25,Table3[Deficiency Category],"?*")) -> 0
E26: {=IFERROR(INDEX(_xlfn.ANCHORARRAY($P$9),ROW()-16),"")} -> Montcalm Mine | F26: =IF($E26="","",COUNTIFS(Table3[Site],$E26,Table3[Deficiency Category],"?*")) -> 0
E27: {=IFERROR(INDEX(_xlfn.ANCHORARRAY($P$9),ROW()-16),"")} | F27: =IF($E27="","",COUNTIFS(Table3[Site],$E27,Table3[Deficiency Category],"?*"))
E28: {=IFERROR(INDEX(_xlfn.ANCHORARRAY($P$9),ROW()-16),"")} | F28: =IF($E28="","",COUNTIFS(Table3[Site],$E28,Table3[Deficiency Category],"?*"))
E29: Total | F29: =SUM(F17:F28) -> 2
A32: RISK PROFILE (Glencore Matrix)
A33: Findings by Risk Rating | H33: Risk Rating | I33: Count
H34: High Risk (17-25) | I34: =COUNTIF(Table3[Risk Rating],"High") -> 1
H35: Medium Risk (7-16) | I35: =COUNTIF(Table3[Risk Rating],"Medium") -> 1
A36: Risk Matrix (Consequence x Likelihood) | H36: Low Risk (1-6) | I36: =COUNTIF(Table3[Risk Rating],"Low") -> 0
A37: Consequence \ Likelihood | B37: A-Almost Certain | C37: B-Likely | D37: C-Possible | E37: D-Unlikely | F37: E-Rare
A38: 5 - Catastrophic | B38: =COUNTIFS(Table3[Consequence Severity],"5*",Table3[Likelihood],"A*") -> 0 | C38: =COUNTIFS(Table3[Consequence Severity],"5*",Table3[Likelihood],"B*") -> 0 | D38: =COUNTIFS(Table3[Consequence Severity],"5*",Table3[Likelihood],"C*") -> 0 | E38: =COUNTIFS(Table3[Consequence Severity],"5*",Table3[Likelihood],"D*") -> 0 | F38: =COUNTIFS(Table3[Consequence Severity],"5*",Table3[Likelihood],"E*") -> 0
A39: 4 - Major | B39: =COUNTIFS(Table3[Consequence Severity],"4*",Table3[Likelihood],"A*") -> 0 | C39: =COUNTIFS(Table3[Consequence Severity],"4*",Table3[Likelihood],"B*") -> 0 | D39: =COUNTIFS(Table3[Consequence Severity],"4*",Table3[Likelihood],"C*") -> 0 | E39: =COUNTIFS(Table3[Consequence Severity],"4*",Table3[Likelihood],"D*") -> 0 | F39: =COUNTIFS(Table3[Consequence Severity],"4*",Table3[Likelihood],"E*") -> 0
A40: 3 - Moderate | B40: =COUNTIFS(Table3[Consequence Severity],"3*",Table3[Likelihood],"A*") -> 0 | C40: =COUNTIFS(Table3[Consequence Severity],"3*",Table3[Likelihood],"B*") -> 1 | D40: =COUNTIFS(Table3[Consequence Severity],"3*",Table3[Likelihood],"C*") -> 0 | E40: =COUNTIFS(Table3[Consequence Severity],"3*",Table3[Likelihood],"D*") -> 0 | F40: =COUNTIFS(Table3[Consequence Severity],"3*",Table3[Likelihood],"E*") -> 0
A41: 2 - Minor | B41: =COUNTIFS(Table3[Consequence Severity],"2*",Table3[Likelihood],"A*") -> 0 | C41: =COUNTIFS(Table3[Consequence Severity],"2*",Table3[Likelihood],"B*") -> 0 | D41: =COUNTIFS(Table3[Consequence Severity],"2*",Table3[Likelihood],"C*") -> 0 | E41: =COUNTIFS(Table3[Consequence Severity],"2*",Table3[Likelihood],"D*") -> 0 | F41: =COUNTIFS(Table3[Consequence Severity],"2*",Table3[Likelihood],"E*") -> 0
A42: 1 - Negligible | B42: =COUNTIFS(Table3[Consequence Severity],"1*",Table3[Likelihood],"A*") -> 1 | C42: =COUNTIFS(Table3[Consequence Severity],"1*",Table3[Likelihood],"B*") -> 0 | D42: =COUNTIFS(Table3[Consequence Severity],"1*",Table3[Likelihood],"C*") -> 0 | E42: =COUNTIFS(Table3[Consequence Severity],"1*",Table3[Likelihood],"D*") -> 0 | F42: =COUNTIFS(Table3[Consequence Severity],"1*",Table3[Likelihood],"E*") -> 0

Sheet Details
A1: Site | B1: Parent Asset | C1: Category | D1: Component | E1: Sub-Component | F1: Location Description | G1: Deficiency Categories | H1: Deficiency Description | I1: Priority | J1: Condition
A2: Blackbird Mine | B2: Blower Building | C2: Building Envelope | D2: Roofing | E2: Membrane / metal roof | F2: British Colombia | G2: CML - Corrosion & Material Loss | H2: Corrosion - Internal | I2: P1 | J2: Critical Condition - Immediate action required
A3: Brenda Mine | B3: B-Mine Pump House | C3: Structural Support | D3: Building Structure | E3: Metal / panel | F3: New Brunswick | G3: CND - Concrete Deterioration | H3: Corrosion - External | I3: P2 | J3: Poor Condition - Repair actions needed within 12 months
A4: Bell Mine | B4: Water Treatment Plant | C4: Foundations & Geotechnical | D4: Storage Tank | E4: Slab-on-grade | F4: Ontario | G4: CFI - Connection & Joint Failures | H4: Loose / Missing Fittings | I4: P3 | J4: Bad Condition - Repairs needed within 24 to 36 months
A5: Grey Eagle Mine | B5: Shop/Storage Building | C5: Process Equipment | D5: Floor Plate | E5: Steel / concrete | F5: Quebec | G5: CRK - Cracking Mechanisms | H5: Fire Damage | I5: P4 | J5: Fair Condition - Monitor before next scheduled inspection
A6: Geco/Wilroy Mine | B6: Buffer Pond Pump House | C6: Others | D6: Grating | E6: Steel | G6: DFI - Deformation & Mechanical Damage | H6: Vehicle / Impact Damage | I6: P5 | J6: Good Condition - No repairs required
A7: Heath Steele Mine | B7: Fresh Water Pump House | D7: Concrete floors / slabs | E7: Steel grating | G7: EWF - Envelope Failure | H7: Deterioration / Wear
A8: Mattabi Mine | B8: Chandlers Pump House | D8: Foundation Pier | E8: Steel stairs | G8: ENV - Environmental & External Damage | H8: Environmental Damage
A9: Matagami Mine | B9: Chandlers Seepage Pump House | D9: Access Ladder | E9: Fixed ladder | G9: FDS - Foundation & Settlement | H9: Poor Maintenance
A10: Brunswick Mine | B10: Portal Pump House | D10: Confined Space | E10: Grouted steel base | G10: GHK - General Housekeeping & Maintenance | H10: Unauthorized Modification
A11: Montcalm Mine | B11: Stratmat Pump House | D11: Column | E11: Concrete ringwall | G11: MSI - Modification & Structural Integrity | H11: Subsidence / Erosion
B12: Mosquito Ditch Pump House | D12: Stairway | G12: THR - Fire & Thermal Damage | H12: Pest Damage
B13: Reactor Tank | D13: Cable Tray | G13: SIE - Soil Instability & Erosion | H13: Coating Failure
B14: LSTR Pump House | D14: Platform | G14: FH - Frost Heave | H14: Cracking
B15: Administrative Building | D15: Catwalks&Walkways | G15: BCF - Bearing Capacity Failure | H15: Spalling
B16: Warehouse | D16: Handrails & Guardrails | G16: PF - Pile Foundations | H16: Deformation / Distortion
B17: Flume House | D17: Fixed Ladders & Cages | H17: Section Loss
B18: LDS Pond | D18: Wall Cladding | H18: Settlement / Movement
B19: Sludge Pumphouse | D19: Cable Tray Support | H19: Water Ingress
D20: Pipe Support | H20: Loose fasteners
D21: Pump Support | H21: Missing components
D22: Beams / framing | H22: Stability
D23: Bracing | H23: Exposed reinforcement
D24: Roof Mounted Unit | H24: Missing bolts or welds
D25: Clarifier Tank | H25: Sagging
D26: Lime Silo | H26: Signs of overstress
D27: Structural columns (building) | H27: Missing or deteriorated insulation
H28: Steel deck deterioration
H29: Delamination
D30: Others | E30: Others | H30: Missing grout under baseplates/columns

Sheet Taxonomy
A1: ASSET TAXONOMY (consolidated from Building Envelope, Structural Support, Foundations & Geotechnical)
A2: Category | B2: Scope | C2: Component | D2: Sub-component | E2: Focus Area | F2: Deficiency Category | G2: Indications
A3: Building Envelope | B3: Structural/building elements not tied to process loads | C3: Roofing systems | D3: Membrane / metal roof | E3: Weatherproofing / water barrier | F3: EWF - Envelope Failure | G3: Water ingress / leaks
A4: Building Envelope | B4: Structural/building elements not tied to process loads | C4: Roofing systems | D4: Membrane / metal roof | E4: Deck / structural support | F4: CML - Corrosion & Material Loss | G4: Corrosion of steel deck
A5: Building Envelope | B5: Structural/building elements not tied to process loads | C5: Roofing systems | D5: Membrane / metal roof | E5: Structural integrity | F5: DFI - Deformation & Mechanical Damage | G5: Sagging / deformation
A6: Building Envelope | B6: Structural/building elements not tied to process loads | C6: Wall cladding | D6: Metal / panel | E6: Envelope protection | F6: EWF - Envelope Failure | G6: Water ingress
A7: Building Envelope | B7: Structural/building elements not tied to process loads | C7: Wall cladding | D7: Metal / panel | E7: External exposure | F7: ENV - Environmental & External Damage | G7: Weather damage (wind/snow)
A8: Building Envelope | B8: Structural/building elements not tied to process loads | C8: Concrete floors / slabs | D8: Slab-on-grade | E8: Load-bearing slab | F8: CND - Concrete Deterioration | G8: Cracking / spalling
A9: Building Envelope | B9: Structural/building elements not tied to process loads | C9: Concrete floors / slabs | D9: Slab-on-grade | E9: Foundation interface | F9: FDS - Foundation & Settlement | G9: Settlement / movement
A10: Building Envelope | B10: Structural/building elements not tied to process loads | C10: Structural columns (building) | D10: Steel / concrete | E10: Vertical load members | F10: CML - Corrosion & Material Loss | G10: Corrosion (exposed steel)
A11: Building Envelope | B11: Structural/building elements not tied to process loads | C11: Structural columns (building) | D11: Steel / concrete | E11: Alignment / plumb | F11: DFI - Deformation & Mechanical Damage | G11: Misalignment / deformation
A12: Building Envelope | B12: Structural/building elements not tied to process loads | C12: Beams / framing | D12: Steel | E12: Primary framing | F12: CRK - Cracking Mechanisms | G12: Fatigue or weld cracking
A13: Building Envelope | B13: Structural/building elements not tied to process loads | C13: Beams / framing | D13: Steel | E13: Load capacity | F13: DFI - Deformation & Mechanical Damage | G13: Deflection / overstress
... A93: Process Equipment (Mechanical) | B93: Equipment directly involved in operations | C93: Pumps | D93: Centrifugal / positive displacement | E93: Hydraulic zones (impeller) | F93: FLW - Flow-Induced Damage | G93: Cavitation damage
A96: DEFICIENCY MECHANISM DICTIONARY (Deficiency Category → Mechanism → Typical Deficiency, by category)
A97: Category | B97: Deficiency Category | C97: Mechanism | D97: Indications
A98: Building Envelope | B98: CML - Corrosion & Material Loss | C98: Atmospheric corrosion (external exposure) | D98: Corrosion of exposed steel members (beams, columns)
A99: Building Envelope | B99: CML - Corrosion & Material Loss | C99: Coating failure / weathering | D99: Rusting of cladding, roofing sheets
A100: Building Envelope | B100: CML - Corrosion & Material Loss | C100: Moisture ingress | D100: Corrosion at roof decks and fasteners
A101: Building Envelope | B101: CRK - Cracking Mechanisms | C101: Thermal movement / expansion | D101: Cracking in concrete slabs and walls
A102: Building Envelope | B102: CRK - Cracking Mechanisms | C102: Shrinkage / aging | D102: Surface cracking in concrete
A103: Building Envelope | B103: CRK - Cracking Mechanisms | C103: Settlement-induced cracking | D103: Diagonal cracks in walls
A104: Building Envelope | B104: DFI - Deformation & Mechanical Damage | C104: Overloading / overstress | D104: Sagging roof structures
A105: Building Envelope | B105: DFI - Deformation & Mechanical Damage | C105: Thermal deformation | D105: Warping of cladding panels
A106: Building Envelope | B106: DFI - Deformation & Mechanical Damage | C106: Impact (vehicles/equipment) | D106: Dented wall panels / damaged guardrails
A107: Building Envelope | B107: ENV - Environmental & External Damage | C107: Snow loads / ice buildup | D107: Roof overstress or collapse risk
A108: Building Envelope | B108: ENV - Environmental & External Damage | C108: Wind loads / storms | D108: Damaged cladding / roofing
... A159: Foundations & Geotechnical | B159: FDS - Foundation & Settlement | C159: Poor compaction | D159: Tilting structures
A160: Foundations & Geotechnical | B160: FDS - Foundation & Settlement | C160: Groundwater fluctuations
A161: Foundations & Geotechnical | B161: SIE - Soil Instability & Erosion | C161: Soil erosion / loss of support material | D161: Voids under foundation
A162: Foundations & Geotechnical | B162: SIE - Soil Instability & Erosion | C162: Poor drainage | D162: Washed-out soil
A163: Foundations & Geotechnical | B163: SIE - Soil Instability & Erosion | C163: Water infiltration
A164: Foundations & Geotechnical | B164: SIE - Soil Instability & Erosion | C164: Lateral soil movement | D164: Horizontal displacement of foundation
A165: Foundations & Geotechnical | B165: FH - Frost Heave | C165: Freeze–thaw cycles | D165: Upward movement
A166: Foundations & Geotechnical | B166: CND - Concrete Deterioration | C166: Freeze–thaw cycles | D166: Spalling
A167: Foundations & Geotechnical | B167: CND - Concrete Deterioration | C167: Chemical attack | D167: Cracking
A168: Foundations & Geotechnical | B168: BCF - Bearing Capacity Failure | C168: Weak bearing soil layer | D168: Sudden settlement
A169: Foundations & Geotechnical | B169: BCF - Bearing Capacity Failure | C169: Overloading | D169: Local bearing failure
A170: Foundations & Geotechnical | B170: PF - Pile Foundations | C170: Misalignment | D170: Inclined piles
A171: Foundations & Geotechnical | B171: PF - Pile Foundations | C171: Insufficient penetration | D171: Broken piles
...

Sheet Lookups
A1: DeficiencyCategory_List | B1: ComponentType_List | C1: Priority_List | D1: YesNo_List | E1: Risk_List | F1: Def_CML | G1: Mech_CML | H1: Def_CND | I1: Mech_CND | J1: Def_CFI | K1: Mech_CFI | L1: Def_CRK | M1: Mech_CRK | N1: Def_DFI | O1: Mech_DFI | P1: Def_EWF | Q1: Mech_EWF | R1: Def_ENV | S1: Mech_ENV | T1: Def_FDS | U1: Mech_FDS | V1: Def_GHK | W1: Mech_GHK | X1: Def_MSI | Y1: Mech_MSI | Z1: Def_THR | AA1: Mech_THR | AB1: Def_SIE | AC1: Mech_SIE | AD1: Def_FH | AE1: Mech_FH | AF1: Def_BCF | AG1: Mech_BCF | AH1: Def_PF | AI1: Mech_PF | AK1: Focus_CML | AL1: Focus_CND | AM1: Focus_CFI | AN1: Focus_CRK | AO1: Focus_DFI | AP1: Focus_EWF | AQ1: Focus_ENV | AR1: Focus_FDS | AS1: Focus_GHK | AT1: Focus_MSI | AU1: Focus_THR | AV1: Focus_SIE | AW1: Focus_FH | AX1: Focus_BCF | AY1: Focus_PF | BA1: Sub_Roofing | BB1: Sub_BuildingStructure | BC1: Sub_StorageTank | BD1: Sub_FloorPlate | BE1: Sub_Grating | BF1: Sub_ConcreteFloor | BG1: Sub_FoundationPier | BH1: Sub_AccessLadder | BI1: Sub_ConfinedSpace | BJ1: Sub_Column | BK1: Sub_Stairway | BL1: Sub_CableTray | BM1: Sub_Platform | BN1: Sub_CatwalksWalkways | BO1: Sub_HandrailsGuardrails | BP1: Sub_FixedLaddersCages | BQ1: Sub_WallCladding | BR1: Sub_CableTraySupport | BS1: Sub_PipeSupport | BT1: Sub_PumpSupport | BU1: Sub_Beams | BV1: Sub_Bracing | BW1: Sub_RoofMountedUnit | BX1: Sub_ClarifierTank | BY1: Sub_LimeSilo | BZ1: Sub_Others
A2: CML - Corrosion & Material Loss | B2: Roofing | C2: P1 | D2: Yes | E2: High | F2: Corrosion of steel deck | G2: Atmospheric corrosion (external exposure) | H2: Cracking / spalling | I2: Freeze-thaw cycles | J2: Loose/missing bolts | K2: Bolt loosening / corrosion | L2: Fatigue or weld cracking | M2: Thermal movement / expansion | N2: Sagging / deformation | O2: Overloading / overstress | P2: Water ingress / leaks | Q2: Membrane / sealant degradation | R2: Weather damage (wind/snow) | S2: Snow loads / ice buildup | T2: Settlement / movement | U2: Soil settlement / movement | V2: Poor maintenance (trip hazards) | W2: Poor inspection / maintenance | X2: Unauthorized modification | Y2: Unauthorized modification | Z2: Fire damage | AA2: Fire exposure | AB2: Voids under foundation | AC2: Soil erosion / loss of support material | AD2: Upward movement | AE2: Freeze-thaw cycles | AF2: Sudden settlement | AG2: Weak bearing soil layer | AH2: Inclined piles | AI2: Misalignment | AK2: Deck / structural support | AL2: Load-bearing slab | AM2: Access / safety | AN2: Primary framing | AO2: Structural integrity | AP2: Weatherproofing / water barrier | AQ2: External exposure | AR2: Foundation interface | AS2: Access systems | AT2: Structural modification control | AU2: Fire exposure / thermal effects | AV2: Drainage paths | AW2: Shallow foundations | AX2: Load transfer zones / foundation-soil interface | AY2: Pile shaft | BA2: Membrane / metal roof | BE2: Steel grating | BF2: Slab-on-grade | BH2: Fixed ladder | BJ2: Steel / concrete | BK2: Steel stairs | BM2: Steel grating | BN2: Steel grating | BO2: Steel | BP2: Fixed ladder | BQ2: Metal / panel | BR2: Steel frame | BS2: Spring / rigid | BT2: Grouted steel base | BU2: Steel
A3: CND - Concrete Deterioration | B3: Building Structure | C3: P2 | D3: No | E3: Medium | F3: Corrosion (exposed steel) | G3: Coating failure / weathering | H3: Spalling | I3: Reinforcement corrosion | J3: Missing or loose fittings | K3: Anchor failure | L3: Fatigue cracking | M3: Shrinkage / aging | N3: Misalignment / deformation | O3: Thermal deformation | P3: Water ingress | Q3: Flashing / joint failure | R3: Vehicle / equipment impact damage | S3: Wind loads / storms | T3: Settlement / differential settlement | U3: Frost heave | V3: Trip hazards (damaged grating) | W3: Missing components | X3: Poor maintenance / missing components | Y3: Addition without design review | Z3: Loss of strength in steel members | AA3: Thermal shock | AB3: Washed-out soil | AC3: Poor drainage | AD3: Cracking and lifting | AF3: Local collapse | AG3: Overloading | AH3: Broken piles | AI3: Insufficient penetration | AK3: Vertical load members | AL3: Concrete integrity / load distribution | AM3: Safety barriers | AN3: Fatigue-prone structural elements | AO3: Alignment / plumb | AP3: Envelope protection | AQ3: External impact exposure | AR3: Soil interaction & bearing support | AT3: Maintenance condition | AV3: Perimeter zones | AW3: Frost-susceptible soils | AX3: Load concentration zones / high stress areas | AY3: Toe / bearing layer
A4: CFI - Connection & Joint Failures | B4: Storage Tank | C4: P3 | E4: Low | F4: Corrosion of grating | G4: Moisture ingress | H4: Surface cracking / structural cracks | I4: Chemical attack | J4: Anchor bolt failure | K4: Sealant degradation | L4: Cracks at welds | M4: Settlement-induced cracking | N4: Deflection / overstress | O4: Impact (vehicles/equipment) | Q4: Weathering / UV degradation | R4: Environmental degradation (snow, rain, wind) | S4: Water ingress (rain) | T4: Erosion around foundation | U4: Poor drainage | V4: Missing guardrails or covers | W4: Lack of cleaning | X4: Improper removal of structural elements | Y4: Improper installation | Z4: Cracking in concrete surfaces | AA4: Thermal expansion stress | AB4: Undermining of foundation | AC4: Water infiltration | AF4: Local bearing failure | AH4: Pile cracking / structural failure | AI4: Structural defects (pile integrity issues) | AK4: Corrosion-prone zones | AL4: Footings / concrete foundation base | AM4: Anchorage system | AN4: Critical welded connections | AO4: Load capacity | AQ4: Environmental exposure | AR4: Soil erosion / drainage | AV4: Drainage interface / water ingress zones | AY4: Pile body integrity / structural continuity
A5: CRK - Cracking Mechanisms | B5: Floor Plate | C5: P4 | F5: Section loss / corrosion | G5: Atmospheric corrosion | H5: Spalling and surface scaling | I5: Freeze-thaw damage | J5: Loose or missing fasteners | K5: Anchor bolt failure | L5: Cracking in concrete slabs and walls | M5: Fatigue (cyclic loading) | N5: Deformation / instability | O5: Overstress / excessive loading | Q5: Water ingress (rain) | R5: Subsidence / erosion | S5: UV degradation | T5: Missing grout under baseplate | U5: Differential settlement | V5: Debris accumulation | W5: Poor maintenance | X5: Overloading of platforms or beams | Z5: Weakening of structural steel | AB5: Horizontal displacement of foundation | AC5: Lateral soil movement | AK5: Access flooring | AL5: Pedestals / localized load supports | AM5: Support fixation & connections | AO5: Access / safety systems | AQ5: External exposure / hazards | AR5: Baseplate support & grout
A6: DFI - Deformation & Mechanical Damage | B6: Grating | C6: P5 | F6: Corrosion at contact points | G6: Water accumulation at baseplates | H6: Exposed rebar in concrete | J6: Missing or loose anchor bolts | K6: Bolt loosening / creep | L6: Surface cracking in concrete | M6: Stress concentration | N6: Misalignment due to movement | O6: Equipment-induced vibration | Q6: Thermal movement / expansion | R6: Impact damage (vehicles) | S6: Weather exposure | T6: Grout deterioration | U6: Soil movement / erosion | V6: Rusted or unmaintained supports | W6: Lack of inspection | X6: Altered supports without design review | Z6: Distortion of structures | AK6: Corrosion-prone contact points | AM6: Anchorage / fixing system | AO6: Alignment & load transfer | AQ6: Ground stability | AR6: Grout interface
A7: EWF - Envelope Failure | B7: Concrete Floor | F7: Corrosion of structural steel | G7: Coating failure | H7: Degraded concrete surfaces | J7: Loose handrails / guardrails | K7: Weld defects | L7: Diagonal cracks in walls | M7: Overloading | N7: Overloaded / bent supports | O7: Impact (vehicles) | R7: Roof overstress or collapse risk | S7: Wind loads | T7: Uneven settlement | U7: Missing / degraded grout | V7: Missing braces or bolts | X7: Misaligned or undersized supports | AK7: Structural steel integrity | AO7: Structural capacity / load support | AR7: Foundation footprint / global bearing area
A8: ENV - Environmental & External Damage | B8: Foundation Pier | F8: Corrosion / coating failure | H8: Spalling at pedestals | J8: Missing or weak anchorage | L8: Cracks at welds of supports | N8: Structural deformation | O8: Foundation movement | R8: Damaged cladding / roofing | S8: Chemical exposure | T8: Cracking of foundations | U8: Drainage issues | V8: Undetected degradation | AK8: Secondary structural support | AO8: Load-bearing structure | AR8: Bearing soil zones / load-support areas
A9: FDS - Foundation & Settlement | B9: Access Ladder | F9: Corrosion of exposed steel members (beams, columns) | H9: Degraded concrete bases | J9: Joint leakage in cladding | L9: Cracking at baseplates or connections | N9: Distortion under load | R9: Leaks through roof or walls | T9: Tilting structures | U9: Soil consolidation | AO9: Load frame / skid integrity | AR9: Subgrade support / compacted layers
A10: GHK - General Housekeeping & Maintenance | B10: Confined Space | F10: Rusting of cladding, roofing sheets | H10: Cracked foundations | J10: Missing or broken anchor bolts | L10: Cracks in structural members | N10: Overstress / deformation | R10: Deterioration of coatings / sealants | T10: Loss of soil stiffness / bearing capacity | U10: Poor compaction | AO10: Primary load path | AR10: Groundwater table / saturated soil zones
A11: MSI - Modification & Structural Integrity | B11: Column | F11: Corrosion at roof decks and fasteners | H11: Cracking | J11: Loose connections at supports | N11: Sagging roof structures | R11: Corrosion due to rain/snow | T11: Uneven floors / slab settlement | U11: Groundwater fluctuations
A12: THR - Fire & Thermal Damage | B12: Stairway | F12: Corrosion of structural steel supports | J12: Weld failure at beams/joints | N12: Warping of cladding panels | R12: Movement or instability of supports | T12: Cracking or lifting of slabs
A13: SIE - Soil Instability & Erosion | B13: Cable Tray | F13: Corrosion at column bases | N13: Dented wall panels / damaged guardrails | R13: Corrosion from process leaks | T13: Water accumulation under slabs
A14: FH - Frost Heave | B14: Platform | F14: Rusted pipe racks / frames | N14: Bent pipe supports | T14: Misalignment of pumps or equipment
A15: BCF - Bearing Capacity Failure | B15: Catwalks&Walkways | N15: Distorted supports / frames | T15: Tilted structures
A16: PF - Pile Foundations | B16: Handrails & Guardrails | N16: Damaged columns or racks | T16: Gaps under baseplates
B17: Fixed Ladders & Cages | N17: Misaligned equipment bases | T17: Undermining of foundations
B18: Wall Cladding | T18: Cracking of slabs/foundations
B19: Cable Tray Support
B20: Pipe Support
B21: Pump Support
B22: Beams
B23: Bracing
B24: Roof Mounted Unit
B25: Clarifier Tank
B26: Lime Silo
B27: Others
